#VRML_SIM R2021a utf8
WorldInfo {
  info [
    ""
    ""
  ]
  title "FLIPPY SIM AUTO"
  physics "flippy_physics"
  basicTimeStep 4
  FPS 30
  coordinateSystem "NUE"
  contactProperties [
    ContactProperties {
      bounce 0.4
    }
  ]
}
Viewpoint {
  fieldOfView 1.2
  orientation 0 1 0 -1.5707996938995747
  position -1.040670688748449 0.025720137886175783 -0.5131739804829633
  follow "F000"
}
Background {
  skyColor [
    0.7 0.7 0.7
    0 0 0
    0 0 0
    0 0 0
    0 0 0
  ]
  backUrl [
    "textures/cubic/dusk_back.png"
  ]
  bottomUrl [
    "textures/cubic/dusk_bottom.png"
  ]
  frontUrl [
    "textures/cubic/dusk_front.png"
  ]
  leftUrl [
    "textures/cubic/dusk_left.png"
  ]
  rightUrl [
    "textures/cubic/dusk_right.png"
  ]
  topUrl [
    "textures/cubic/dusk_top.png"
  ]
}
DirectionalLight {
  ambientIntensity 1
  direction -1 -0.5 -1
  intensity 1.5
}
DEF floor1 Solid {
  children [
    DEF floor_shape Shape {
      appearance PBRAppearance {
        baseColorMap ImageTexture {
          url [
            "textures/tiles.jpg"
          ]
        }
        transparency 0.01
        roughness 0.5
        metalness 0.5
      }
      geometry Box {
        size 1 0.01 1.00578
      }
    }
    DEF floor_connector Connector {
      name "floor_connector"
      model "flippy_stick"
      boundingObject USE floor_shape
      physics Physics {
      }
      type "passive"
      autoLock TRUE
      distanceTolerance 10
      axisTolerance 3.14
      rotationTolerance 3.141592653589793
      numberOfRotations 0
      snap FALSE
    }
  ]
  boundingObject USE floor_shape
}
DEF floor2 Solid {
  translation 0 0 -0.5
  rotation 1 0 0 -1.0471996938995747
  children [
    DEF floor2_shape Transform {
      translation 0 0 -0.5
      children [
        USE floor_shape
      ]
    }
  ]
  name "solid(1)"
  boundingObject USE floor2_shape
}
DEF floor3 Solid {
  translation 0 0 -1.5
  rotation 1 0 0 1.0471996938995747
  children [
    DEF floor3_shape Transform {
      translation 0 0 0.5
      children [
        USE floor_shape
      ]
    }
  ]
  name "solid(2)"
  boundingObject USE floor3_shape
}
DEF floor4 Solid {
  translation 0 0 -1.9988
  rotation 1 0 0 0
  children [
    USE floor_shape
  ]
  name "solid(3)"
  boundingObject USE floor_shape
}
Robot {
  translation -0.00572612 0.07973568 -0.45697551
  rotation -0.2504856796959769 0.9348252888653704 -0.2517113496944893 1.63327005
  children [
    DEF FlippyParts Group {
      children [
        DEF FLIPPY_BODY Solid {
          rotation 0 0 1 -1.5708003061004252
          children [
            DEF BODY Shape {
              appearance DEF RED PBRAppearance {
                baseColor 1 0.2 0.2
                roughness 1
                metalness 0
              }
              geometry Cylinder {
                height 0.01
                radius 0.01
              }
            }
          ]
          name "solid(2)"
          boundingObject USE BODY
          physics Physics {
          }
        }
        DEF H1 Hinge2Joint {
          jointParameters HingeJointParameters {
            axis 0 0 1
            anchor 0.025 0 0
          }
          jointParameters2 JointParameters {
            axis 0 -1 0
          }
          device [
            PositionSensor {
              name "P1"
            }
            RotationalMotor {
              name "M1"
              maxVelocity 100
            }
          ]
          device2 [
            PositionSensor {
              name "RP1"
            }
            RotationalMotor {
              name "RM1"
            }
          ]
          endPoint DEF F000_S1 Solid {
            translation 0.025 0 0
            rotation -1 0 0 0
            children [
              DEF S1 Group {
                children [
                  DEF HS11 Transform {
                    children [
                      hemisphere {
                        color 0.4 0.9 0.4
                      }
                    ]
                  }
                  DEF HS12 Transform {
                    rotation 1 0 0 3.1415
                    children [
                      hemisphere {
                        color 0.1 0.7 0.1
                      }
                    ]
                  }
                ]
              }
              DEF T11 TouchSensor {
                name "T11"
                boundingObject USE HS11
                physics DEF BUMP_PHYSICS Physics {
                }
              }
              DEF T12 TouchSensor {
                name "T12"
                boundingObject USE HS12
                physics DEF BUMP_PHYSICS Physics {
                }
              }
              Receiver {
                name "RS1"
              }
              Emitter {
                name "ES1"
                range 0.061
              }
            ]
            name "s1"
            boundingObject USE S1
            physics DEF S_PHYSICS Physics {
            }
          }
        }
        DEF H2 Hinge2Joint {
          jointParameters HingeJointParameters {
            axis 0 0 1
            anchor -0.025 0 0
          }
          jointParameters2 JointParameters {
            axis 0 1 0
          }
          device [
            PositionSensor {
              name "P2"
            }
            RotationalMotor {
              name "M2"
              maxVelocity 100
            }
          ]
          device2 [
            PositionSensor {
              name "RP2"
            }
            RotationalMotor {
              name "RM2"
            }
          ]
          endPoint DEF F000_S2 Solid {
            translation -0.025 0 0
            rotation -1 0 0 0
            children [
              DEF S2 Group {
                children [
                  DEF HS21 Transform {
                    children [
                      hemisphere {
                        color 0.4 0.4 1
                      }
                    ]
                  }
                  DEF HS22 Transform {
                    rotation 1 0 0 3.1415
                    children [
                      hemisphere {
                        color 0.1 0.1 0.7
                      }
                    ]
                  }
                ]
              }
              DEF T21 TouchSensor {
                name "T21"
                boundingObject USE HS21
                physics DEF BUMP_PHYSICS Physics {
                }
              }
              DEF T22 TouchSensor {
                name "T22"
                boundingObject USE HS22
                physics DEF BUMP_PHYSICS Physics {
                }
              }
              Receiver {
                name "RS2"
              }
              Emitter {
                name "ES2"
                range 0.061
              }
            ]
            name "s2"
            boundingObject USE S2
            physics USE S_PHYSICS
          }
        }
        Receiver {
          name "R1"
        }
        Emitter {
          name "E1"
        }
        InertialUnit {
          name "IU"
        }
        GPS {
          name "GPS"
        }
      ]
    }
  ]
  name "F000"
  boundingObject USE BODY
  physics USE S_PHYSICS
  controller "flippy_controller"
  controllerArgs [
    "0"
  ]
}
Robot {
  translation -0.00953201 0.08552337 -0.25301363
  rotation -0.2506440310336779 0.9354162538577382 -0.2493471510283294 1.64268559
  children [
    DEF FlippyParts Group {
      children [
        DEF FLIPPY_BODY Solid {
          rotation 0 0 1 -1.5708003061004252
          children [
            DEF BODY Shape {
              appearance DEF RED PBRAppearance {
                baseColor 1 0.2 0.2
                roughness 1
                metalness 0
              }
              geometry Cylinder {
                height 0.01
                radius 0.01
              }
            }
          ]
          name "solid(2)"
          boundingObject USE BODY
          physics Physics {
          }
        }
        DEF H1 Hinge2Joint {
          jointParameters HingeJointParameters {
            axis 0 0 1
            anchor 0.025 0 0
          }
          jointParameters2 JointParameters {
            axis 0 -1 0
          }
          device [
            PositionSensor {
              name "P1"
            }
            RotationalMotor {
              name "M1"
              maxVelocity 100
            }
          ]
          device2 [
            PositionSensor {
              name "RP1"
            }
            RotationalMotor {
              name "RM1"
            }
          ]
          endPoint DEF F001_S1 Solid {
            translation 0.025 0 0
            rotation -1 0 0 0
            children [
              DEF S1 Group {
                children [
                  DEF HS11 Transform {
                    children [
                      hemisphere {
                        color 0.4 0.9 0.4
                      }
                    ]
                  }
                  DEF HS12 Transform {
                    rotation 1 0 0 3.1415
                    children [
                      hemisphere {
                        color 0.1 0.7 0.1
                      }
                    ]
                  }
                ]
              }
              DEF T11 TouchSensor {
                name "T11"
                boundingObject USE HS11
                physics DEF BUMP_PHYSICS Physics {
                }
              }
              DEF T12 TouchSensor {
                name "T12"
                boundingObject USE HS12
                physics DEF BUMP_PHYSICS Physics {
                }
              }
              Receiver {
                name "RS1"
              }
              Emitter {
                name "ES1"
                range 0.061
              }
            ]
            name "s1"
            boundingObject USE S1
            physics DEF S_PHYSICS Physics {
            }
          }
        }
        DEF H2 Hinge2Joint {
          jointParameters HingeJointParameters {
            axis 0 0 1
            anchor -0.025 0 0
          }
          jointParameters2 JointParameters {
            axis 0 1 0
          }
          device [
            PositionSensor {
              name "P2"
            }
            RotationalMotor {
              name "M2"
              maxVelocity 100
            }
          ]
          device2 [
            PositionSensor {
              name "RP2"
            }
            RotationalMotor {
              name "RM2"
            }
          ]
          endPoint DEF F001_S2 Solid {
            translation -0.025 0 0
            rotation -1 0 0 0
            children [
              DEF S2 Group {
                children [
                  DEF HS21 Transform {
                    children [
                      hemisphere {
                        color 0.4 0.4 1
                      }
                    ]
                  }
                  DEF HS22 Transform {
                    rotation 1 0 0 3.1415
                    children [
                      hemisphere {
                        color 0.1 0.1 0.7
                      }
                    ]
                  }
                ]
              }
              DEF T21 TouchSensor {
                name "T21"
                boundingObject USE HS21
                physics DEF BUMP_PHYSICS Physics {
                }
              }
              DEF T22 TouchSensor {
                name "T22"
                boundingObject USE HS22
                physics DEF BUMP_PHYSICS Physics {
                }
              }
              Receiver {
                name "RS2"
              }
              Emitter {
                name "ES2"
                range 0.061
              }
            ]
            name "s2"
            boundingObject USE S2
            physics USE S_PHYSICS
          }
        }
        Receiver {
          name "R1"
        }
        Emitter {
          name "E1"
        }
        InertialUnit {
          name "IU"
        }
        GPS {
          name "GPS"
        }
      ]
    }
  ]
  name "F001"
  boundingObject USE BODY
  physics USE S_PHYSICS
  controller "flippy_controller"
  controllerArgs [
    "0"
  ]
}
